{"errorMessage":"Lambda process returned error status code: 1. Result: {\"errorMessage\": \"An error occurred (InvalidAccessKeyId) when calling the GetObject operation: The AWS Access Key Id you provided does not exist in our records.\", \"errorType\": \"ClientError\", \"stackTrace\": [[\"/var/task/index.py\", 13, \"handler\", \"response = s3.get_object(Bucket=bucket, Key=key)\"], [\"/var/runtime/botocore/client.py\", 357, \"_api_call\", \"return self._make_api_call(operation_name, kwargs)\"], [\"/var/runtime/botocore/client.py\", 661, \"_make_api_call\", \"raise error_class(parsed_response, operation_name)\"]]}. Output:\nSTART RequestId: 3b2a0706-b3fb-434f-b536-55f97d5f5f87 Version: $LATEST\nAn error occurred (InvalidAccessKeyId) when calling the GetObject operation: The AWS Access Key Id you provided does not exist in our records.: ClientError\nTraceback (most recent call last):\n  File \"/var/task/index.py\", line 13, in handler\n    response = s3.get_object(Bucket=bucket, Key=key)\n  File \"/var/runtime/botocore/client.py\", line 357, in _api_call\n    return self._make_api_call(operation_name, kwargs)\n  File \"/var/runtime/botocore/client.py\", line 661, in _make_api_call\n    raise error_class(parsed_response, operation_name)\nbotocore.exceptions.ClientError: An error occurred (InvalidAccessKeyId) when calling the GetObject operation: The AWS Access Key Id you provided does not exist in our records.\n\nEND RequestId: 3b2a0706-b3fb-434f-b536-55f97d5f5f87\nREPORT RequestId: 3b2a0706-b3fb-434f-b536-55f97d5f5f87 Duration: 1037 ms Billed Duration: 1100 ms Memory Size: 1536 MB Max Memory Used: 34 MB","errorType":"InvocationException","stackTrace":["  File \"/opt/code/localstack/localstack/services/awslambda/lambda_api.py\", line 574, in run_lambda\n    result = LAMBDA_EXECUTOR.execute(func_arn, func_details, event, context=context,\n","  File \"/opt/code/localstack/localstack/services/awslambda/lambda_executors.py\", line 176, in execute\n    return do_execute()\n","  File \"/opt/code/localstack/localstack/services/awslambda/lambda_executors.py\", line 168, in do_execute\n    return _run(func_arn=func_arn)\n","  File \"/opt/code/localstack/localstack/utils/cloudwatch/cloudwatch_util.py\", line 149, in wrapped\n    raise e\n","  File \"/opt/code/localstack/localstack/utils/cloudwatch/cloudwatch_util.py\", line 145, in wrapped\n    result = func(*args, **kwargs)\n","  File \"/opt/code/localstack/localstack/services/awslambda/lambda_executors.py\", line 159, in _run\n    raise e\n","  File \"/opt/code/localstack/localstack/services/awslambda/lambda_executors.py\", line 147, in _run\n    result = self._execute(func_arn, func_details, event, context, version)\n","  File \"/opt/code/localstack/localstack/services/awslambda/lambda_executors.py\", line 325, in _execute\n    result = self.run_lambda_executor(cmd, stdin, env_vars=environment, func_details=func_details)\n","  File \"/opt/code/localstack/localstack/services/awslambda/lambda_executors.py\", line 231, in run_lambda_executor\n    raise InvocationException('Lambda process returned error status code: %s. Result: %s. Output:\\n%s' %\n"]}
